<?xml version="1.0" encoding="utf-8"?>
<!-- This URDF was automatically created by SolidWorks to URDF Exporter! Originally created by Stephen Brawner (brawner@gmail.com) 
     Commit Version: 1.6.0-1-g15f4949  Build Version: 1.6.7594.29634
     For more information, please see http://wiki.ros.org/sw_urdf_exporter -->
<robot
  name="v6">
  <link
    name="base_link">
    <inertial>
      <origin
        xyz="0.01039 8.6308E-05 0.00018678"
        rpy="0 0 0" />
      <mass
        value="0.37766" />
      <inertia
        ixx="0.00016094"
        ixy="-7.2687E-08"
        ixz="6.3886E-08"
        iyy="0.00011183"
        iyz="2.8019E-07"
        izz="6.5676E-05" />
    </inertial>
    <visual>
      <origin
        xyz="0 0 0"
        rpy="0 0 0" />
      <geometry>
        <mesh
          filename="package://meshes/base_link.STL" />
      </geometry>
      <material
        name="">
        <color
          rgba="0.75294 0.75294 0.75294 1" />
      </material>
    </visual>
    <collision>
      <origin
        xyz="0 0 0"
        rpy="0 0 0" />
      <geometry>
        <mesh
          filename="package://meshes/base_link.STL" />
      </geometry>
    </collision>
  </link>
  <link
    name="hip">
    <inertial>
      <origin
        xyz="0.0027379 -0.00020066 -0.056426"
        rpy="0 0 0" />
      <mass
        value="0.53716" />
      <inertia
        ixx="0.00057698"
        ixy="1.5435E-06"
        ixz="-1.1156E-08"
        iyy="0.00033506"
        iyz="1.9459E-08"
        izz="0.00034484" />
    </inertial>
    <visual>
      <origin
        xyz="0 0 0"
        rpy="0 0 0" />
      <geometry>
        <mesh
          filename="package://meshes/hip.STL" />
      </geometry>
      <material
        name="">
        <color
          rgba="0.75294 0.75294 0.75294 1" />
      </material>
    </visual>
    <collision>
      <origin
        xyz="0 0 0"
        rpy="0 0 0" />
      <geometry>
        <mesh
          filename="package://meshes/hip.STL" />
      </geometry>
    </collision>
  </link>
  <joint
    name="urdf_force_sensor"
    type="fixed">
    <origin
      xyz="0.036 0 0"
      rpy="1.5708 0 -1.5708" />
    <parent
      link="base_link" />
    <child
      link="hip" />
    <axis
      xyz="0 0 0" />
  </joint>
  <link
    name="link1">
    <inertial>
      <origin
        xyz="0.054312 6.3584E-06 0.039428"
        rpy="0 0 0" />
      <mass
        value="1.2086" />
      <inertia
        ixx="0.00062066"
        ixy="-1.8972E-07"
        ixz="1.6441E-06"
        iyy="0.00095221"
        iyz="-6.5074E-08"
        izz="0.0013698" />
    </inertial>
    <visual>
      <origin
        xyz="0 0 0"
        rpy="0 0 0" />
      <geometry>
        <mesh
          filename="package://meshes/link1.STL" />
      </geometry>
      <material
        name="">
        <color
          rgba="0.75294 0.75294 0.75294 1" />
      </material>
    </visual>
    <collision>
      <origin
        xyz="0 0 0"
        rpy="0 0 0" />
      <geometry>
        <mesh
          filename="package://meshes/link1.STL" />
      </geometry>
    </collision>
  </link>
  <joint
    name="urdf_hip"
    type="revolute">
    <origin
      xyz="-0.01525 0 -0.059"
      rpy="1.5708 0 -1.5708" />
    <parent
      link="hip" />
    <child
      link="link1" />
    <axis
      xyz="0 0 1" />
    <limit
      lower="-1.6"
      upper="1.6"
      effort="12"
      velocity="38.2" />
  </joint>
  <link
    name="link2">
    <inertial>
      <origin
        xyz="0.075345 1.0469E-08 -7.387E-05"
        rpy="0 0 0" />
      <mass
        value="0.13548" />
      <inertia
        ixx="2.0106E-05"
        ixy="-5.0085E-13"
        ixz="9.6434E-11"
        iyy="6.3048E-05"
        iyz="-4.4738E-11"
        izz="6.3774E-05" />
    </inertial>
    <visual>
      <origin
        xyz="0 0 0"
        rpy="0 0 0" />
      <geometry>
        <mesh
          filename="package://meshes/link2.STL" />
      </geometry>
      <material
        name="">
        <color
          rgba="0.75294 0.75294 0.75294 1" />
      </material>
    </visual>
    <collision>
      <origin
        xyz="0 0 0"
        rpy="0 0 0" />
      <geometry>
        <mesh
          filename="package://meshes/link2.STL" />
      </geometry>
    </collision>
  </link>
  <joint
    name="urdf_knee"
    type="revolute">
    <origin
      xyz="0.2 0 0.099"
      rpy="0 0 0" />
    <parent
      link="link1" />
    <child
      link="link2" />
    <axis
      xyz="0 0 1" />
    <limit
      effort="12"
      velocity="38.2" />
  </joint>
</robot>
